## Обработка исключений: try...except...finally

В процессе выполнения программы могут возникать ошибки, которые нарушают её нормальное функционирование. Такие ошибки называются исключениями. Python предоставляет механизм обработки исключений, позволяющий перехватывать и обрабатывать ошибки, предотвращая аварийное завершение программы.

### Блок try...except

Основным инструментом обработки исключений является конструкция `try...except`. Её синтаксис выглядит следующим образом:

```python
try:
    # Код, который может вызвать исключение
except <ТипИсключения1>:
    # Код, выполняемый при возникновении исключения типа <ТипИсключения1>
except <ТипИсключения2>:
    # Код, выполняемый при возникновении исключения типа <ТипИсключения2>
...
except Exception:
    # Код, выполняемый при возникновении любого исключения
else:
    # Код, выполняемый, если в блоке try не возникло исключений
```

Рассмотрим каждый элемент конструкции:

* **`try:`**: В этом блоке размещается код, который потенциально может вызвать исключение.
* **`except <ТипИсключения>:`**: Этот блок выполняется, если в блоке `try` произошло исключение указанного типа. Вы можете указать конкретный тип исключения, например, `TypeError`, `ValueError`, `ZeroDivisionError` и т.д.
* **`except Exception:`**:  Этот блок перехватывает любые исключения, не обработанные предыдущими блоками `except`. `Exception` - это базовый класс для всех исключений в Python.
* **`else:`**: Этот блок является опциональным и выполняется только в том случае, если в блоке `try` не возникло никаких исключений.
 
**Пример:**

```python
try:
    # Попытка деления на ноль
    result = 10 / 0
except ZeroDivisionError:
    print("Ошибка: деление на ноль!")
else:
    print("Результат:", result)
```

В этом примере внутри блока `try` происходит деление на ноль, что вызывает исключение `ZeroDivisionError`.  Блок `except ZeroDivisionError` перехватывает это исключение и выводит сообщение об ошибке. Блок `else` в данном случае не выполняется.

### Блок finally

Иногда требуется выполнить определенный код независимо от того, возникло исключение или нет. Для этих целей используется блок `finally`. 

Синтаксис конструкции с блоком `finally`:

```python
try:
    # Код, который может вызвать исключение
except <ТипИсключения1>:
    # Код, выполняемый при возникновении исключения типа <ТипИсключения1>
...
finally:
    # Код, выполняемый всегда (независимо от возникновения исключений)
```

**Пример:**

```python
try:
    file = open("myfile.txt", "r")
    # Работа с файлом
except FileNotFoundError:
    print("Файл не найден!")
finally:
    file.close() # Закрытие файла в любом случае
```

В этом примере блок `finally` гарантирует, что файл будет закрыт независимо от того, был ли он успешно открыт или возникла ошибка `FileNotFoundError`.

### Вызов исключений

Помимо обработки существующих исключений, Python позволяет генерировать собственные исключения с помощью инструкции `raise`. Это может быть полезно для сигнализации об ошибках в вашем коде.

**Пример:**

```python
def check_age(age):
    if age < 18:
        raise ValueError("Доступ запрещен лицам младше 18 лет")
    else:
        print("Доступ разрешен")
        
try:
    check_age(15)
except ValueError as e:
    print(e)
```

В этом примере функция `check_age` проверяет возраст пользователя. Если возраст меньше 18 лет, функция генерирует исключение `ValueError` с сообщением об ошибке.  Блок `try...except` перехватывает это исключение и выводит сообщение.

### Иерархия исключений

Все исключения в Python являются классами, организованными в иерархию. Базовым классом для всех исключений является `BaseException`.  Вы можете создавать собственные классы исключений, наследуясь от `Exception` или его подклассов. 

**Пример:**

```python
class InvalidInputError(Exception):
    pass

def get_user_input():
    value = input("Введите число: ")
    try:
        number = int(value)
    except ValueError:
        raise InvalidInputError("Неверный формат числа")
    return number
```

В этом примере создан собственный класс исключения `InvalidInputError`, наследуемый от `Exception`. Функция `get_user_input` генерирует это исключение, если пользователь вводит некорректное значение.

Обработка исключений является важной частью написания надежного и отказоустойчивого кода. Конструкция `try...except...finally` позволяет контролировать поведение программы при возникновении ошибок и предотвращать аварийное завершение. 
