## Обработка ошибок в Swift

Обработка ошибок — это неотъемлемая часть разработки надёжного и стабильного приложения. В Swift обработка ошибок реализована через механизм, основанный на четырёх ключевых элементах:

* **Ошибка (Error)**: тип, представляющий собой ошибку.
* **Генерирование ошибки (Throwing)**: действие, сигнализирующее о возникновении ошибки.
* **Перехват ошибки (Catching)**: обработка сгенерированной ошибки.
* **Распространение ошибки (Propagating)**: передача информации об ошибке на более высокий уровень для дальнейшей обработки.

### Типы ошибок

В Swift ошибки представляются типами, соответствующими протоколу `Error`. Протокол `Error` не имеет собственных требований, поэтому для представления ошибки можно использовать любой тип, соответствующий этому протоколу. 

```swift
enum NetworkError: Error {
    case badURL
    case noConnection
    case timeout
}
```

В примере выше определено перечисление `NetworkError`, которое соответствует протоколу `Error`. Каждый случай перечисления описывает определённый тип сетевой ошибки.

### Генерирование ошибки

Для сигнализации о возникновении ошибки используется ключевое слово `throw`. Ошибка генерируется в функции с помощью `throw`, за которым следует экземпляр типа, соответствующего протоколу `Error`.

```swift
func fetchData(from urlString: String) throws -> Data {
    guard let url = URL(string: urlString) else {
        throw NetworkError.badURL
    }
    // ... остальной код функции
}
```

В примере выше функция `fetchData(from:)` пытается создать `URL` из переданной строки. Если создание URL невозможно, генерируется ошибка `NetworkError.badURL`.

### Перехват ошибки

Для обработки сгенерированных ошибок используется конструкция `do-catch`.  Блок `do` содержит код, который может генерировать ошибку. Блок `catch` перехватывает и обрабатывает сгенерированную ошибку.

```swift
do {
    let data = try fetchData(from: "https://example.com/data")
    // ... обработка данных
} catch NetworkError.badURL {
    print("Ошибка: неверный URL")
} catch NetworkError.noConnection {
    print("Ошибка: нет соединения с интернетом")
} catch {
    print("Произошла неизвестная ошибка: \(error)")
}
```

В этом примере блок `do` вызывает функцию `fetchData(from:)`. Если функция генерирует ошибку, она перехватывается блоком `catch`.  Каждый блок `catch` обрабатывает определённый тип ошибки. Последний блок `catch` без указания типа ошибки является общим и перехватывает любые ошибки, не обработанные предыдущими блоками.

### Распространение ошибки

Если функция может сгенерировать ошибку, но не обрабатывает её внутри себя, она должна распространить эту ошибку на более высокий уровень. Для этого используется ключевое слово `throws` в объявлении функции.

```swift
func processData(from urlString: String) throws {
    let data = try fetchData(from: urlString)
    // ... обработка данных
}
```

В данном примере функция `processData(from:)` вызывает функцию `fetchData(from:)`, которая может сгенерировать ошибку.  Ключевое слово `throws` в объявлении функции `processData(from:)` указывает на то, что эта функция также может сгенерировать ошибку. 

### Пример обработки ошибки

```swift
enum FileError: Error {
    case fileNotFound
    case fileCorrupted
}

func readFile(atPath path: String) throws -> String {
    guard FileManager.default.fileExists(atPath: path) else {
        throw FileError.fileNotFound
    }
    // ... чтение содержимого файла
}

func printFileContent(atPath path: String) {
    do {
        let content = try readFile(atPath: path)
        print(content)
    } catch FileError.fileNotFound {
        print("Ошибка: файл не найден")
    } catch {
        print("Произошла ошибка при чтении файла: \(error)")
    }
}

let filePath = "/path/to/file.txt"
printFileContent(atPath: filePath)
```

В этом примере определены:

* Перечисление `FileError`, представляющее ошибки чтения файла.
* Функция `readFile(atPath:)`, которая пытается прочитать содержимое файла и генерирует ошибку `FileError.fileNotFound`, если файл не найден.
* Функция `printFileContent(atPath:)`, которая вызывает `readFile(atPath:)` внутри блока `do-catch` и обрабатывает ошибки `FileError.fileNotFound` и любые другие ошибки.

Этот пример демонстрирует базовые принципы обработки ошибок в Swift. Более сложные сценарии могут включать в себя использование `try?`, `try!`, а также обработку ошибок в асинхронном коде. 
