## Обработка ошибок с помощью конструкции try..catch..finally

В процессе разработки JavaScript-приложений не всегда все идет по плану. Непредвиденные ошибки, такие как неверные данные, недоступные ресурсы или ошибки в коде, могут привести к некорректной работе программы и даже к ее остановке. Для управления этими ситуациями JavaScript предоставляет конструкцию `try..catch..finally`, позволяющую перехватывать ошибки и обрабатывать их, предотвращая сбой приложения.

### Базовый синтаксис try..catch

Конструкция `try..catch` состоит из двух основных блоков: `try` и `catch`. В блоке `try` размещается код, который потенциально может вызвать ошибку. Блок `catch` выполняется, если в блоке `try` возникла ошибка.

```javascript
try {
  // Код, который может вызвать ошибку
} catch (error) {
  // Обработка ошибки
}
```

**Пример:**

```javascript
try {
  // Пытаемся получить доступ к несуществующей переменной
  console.log(nonExistentVariable);
} catch (error) {
  // Выводим сообщение об ошибке в консоль
  console.error("Произошла ошибка:", error.message);
}
```

В этом примере мы пытаемся вывести в консоль значение несуществующей переменной `nonExistentVariable`. Это вызовет ошибку `ReferenceError`. Блок `catch` перехватывает эту ошибку, и в консоль выводится сообщение "Произошла ошибка:" вместе с описанием ошибки.

### Объект Error

В блоке `catch` мы получаем доступ к объекту `error`, который содержит информацию о возникшей ошибке. 

**Основные свойства объекта Error:**

| Свойство | Описание |
|---|---|
| `name` | Имя ошибки (например, "ReferenceError", "TypeError", "SyntaxError") |
| `message` | Описание ошибки |
| `stack` | Трассировка стека вызовов, показывающая путь к ошибке в коде |

**Пример использования свойств объекта Error:**

```javascript
try {
  throw new Error("Это пользовательская ошибка.");
} catch (error) {
  console.error("Имя ошибки:", error.name);
  console.error("Описание ошибки:", error.message);
  console.error("Трассировка стека:", error.stack);
}
```

### Блок finally

Конструкция `try..catch` может быть расширена блоком `finally`, который выполняется всегда, независимо от того, была ли ошибка или нет. Блок `finally` обычно используется для выполнения действий, которые необходимо выполнить в любом случае, например, для закрытия соединений, освобождения ресурсов или сброса переменных.

```javascript
try {
  // Код, который может вызвать ошибку
} catch (error) {
  // Обработка ошибки
} finally {
  // Код, который будет выполнен в любом случае
}
```

**Пример:**

```javascript
let file = null;

try {
  // Пытаемся открыть файл
  file = openFile("example.txt");
  // ... работа с файлом ...
} catch (error) {
  console.error("Ошибка при работе с файлом:", error.message);
} finally {
  // Закрываем файл, если он был открыт
  if (file) {
    closeFile(file);
  }
}
```

В этом примере мы открываем файл в блоке `try`. Если при открытии файла произошла ошибка, она будет перехвачена в блоке `catch`. В блоке `finally` мы закрываем файл, если он был успешно открыт.

### Генерация ошибок с помощью throw

JavaScript позволяет генерировать собственные ошибки с помощью оператора `throw`. Это может быть полезно для обработки исключительных ситуаций в вашем коде. 

```javascript
function divide(a, b) {
  if (b === 0) {
    throw new Error("Деление на ноль невозможно.");
  }
  return a / b;
}

try {
  let result = divide(10, 0);
  console.log(result);
} catch (error) {
  console.error(error.message); // Вывод: "Деление на ноль невозможно."
}
```

В этом примере функция `divide` генерирует ошибку `Error` с сообщением "Деление на ноль невозможно", если второй аргумент равен 0. Эта ошибка перехватывается в блоке `catch`, и сообщение об ошибке выводится в консоль.

### Заключение

Конструкция `try..catch..finally` - это мощный инструмент для обработки ошибок в JavaScript. Она позволяет создавать более надежные и отказоустойчивые приложения, обрабатывая непредвиденные ситуации и предотвращая сбои. Используйте `try..catch..finally` для перехвата ошибок, обработки исключительных ситуаций и генерации собственных ошибок, чтобы ваш код был чище, безопаснее и проще в обслуживании. 
